<?xml version="1.0"?>

<robot xmlns:xacro="http://www.ros.org/wiki/xacro" name="smrr">

  <xacro:property name="PI" value="3.14159265359" />

  <xacro:include filename="$(find smrr_description)/urdf/camera.urdf" />
  <xacro:include filename="$(find smrr_description)/urdf/lidar.urdf" />
  <xacro:include filename="$(find smrr_description)/urdf/transmission.urdf" />
  <xacro:include filename="$(find smrr_description)/urdf/gazebo_ros2_control.urdf" /> 
  <xacro:include filename="$(find smrr_description)/urdf/smrr_ros2_control.urdf" />
  <xacro:include filename="$(find smrr_description)/urdf/imu.urdf" />
  
  <link name="base_footprint"/>
  <link
    name="base_link">
    <inertial>
      <origin
        xyz="0.0201310485852864 0.000520829416461865 0.865026738420884"
        rpy="0 0 0" />
      <mass
        value="8.2797481488828" /> <!-- 28.2797481488828 -->
      <!-- <mass
        value="48.2797481488828" /> -->
      <inertia
        ixx="1.40869842198577"
        ixy="0.00172519109922957"
        ixz="0.0295451682055194"
        iyy="1.38963154057563"
        iyz="-0.00609490500279897"
        izz="0.244482664433787" />
    </inertial>
    <visual>
      <origin
        xyz="0 0 0"
        rpy="0 0 0" />
      <geometry>
        <mesh
          filename="package://smrr_description/meshes/base_link.STL" />
      </geometry>
      <material
        name="">
        <color
          rgba="0.643137254901961 0.615686274509804 0.6 1" />
      </material>
    </visual>
    <collision>
      <origin
        xyz="0 0 0"
        rpy="0 0 0" />
      <geometry>
        <mesh
          filename="package://smrr_description/meshes/base_link.STL" />
      </geometry>
    </collision>
  </link>
  <joint
    name="base_joint"
    type="fixed">
    <origin
      xyz="0 0 0"
      rpy="0 0 0" /> 
    <parent
      link="base_footprint" />
    <child
      link="base_link" />
  </joint>

  <link
    name="right_wheel">
    <inertial>
      <origin
        xyz="3.04623488683875E-06 6.72391256367755E-06 -0.0311105168378413"
        rpy="0 0 0" />
      <mass
        value="0.989823090734283" />
      <inertia
        ixx="0.00167921032012111"
        ixy="6.53172867821882E-09"
        ixz="-1.64665780609969E-07"
        iyy="0.0016792904624912"
        iyz="-3.63464523309006E-07"
        izz="0.00288690083815089" />
    </inertial>
    <visual>
      <origin
        xyz="0 0 -0.025"
        rpy="0 0 0" />
      <!-- <geometry>
        <mesh
          filename="package://smrr_description/meshes/right_wheel.STL" />
      </geometry> -->
       <geometry>
        <cylinder radius="0.081" length="0.05"/>
      </geometry>
      <material
        name="">
        <color
          rgba="0.2 0.2 0.2 1" />
      </material>
    </visual>
    <collision>
      <origin
        xyz="0 0 -0.025"
        rpy="0 0 0" />
      <!-- <geometry>
        <mesh
          filename="package://smrr_description/meshes/right_wheel.STL" />
      </geometry> -->
       <geometry>
        <cylinder radius="0.081" length="0.05"/>
      </geometry>
    </collision>
  </link>
  <!-- <joint
    name="right_wheel_joint"
    type="continuous">
    <origin
      xyz="0 -0.201 0.0184000000000001"
      rpy="-1.5707963267949 0 0" />
    <parent
      link="base_link" />
    <child
      link="right_wheel" />
    <axis
      xyz="0 0 1" />
  </joint> -->
  <joint
    name="right_wheel_joint"
    type="continuous">
    <origin
      xyz="0 -0.201 0.0184000000000001"
      rpy="-1.5707963267949 0 0" />
    <parent
      link="base_link" />
    <child
      link="right_wheel" />
    <axis
      xyz="0 0 1" />
    <dynamics damping="0.3" friction="0.5"/>
  </joint>

  <link
    name="left_wheel">
    <inertial>
      <origin
        xyz="-8.38679888204297E-07 7.3339732202804E-06 0.0311105168378413"
        rpy="0 0 0" />
      <mass
        value="0.989823090734282" />
      <inertia
        ixx="0.00167926061595776"
        ixy="-1.12032618333546E-08"
        ixz="-4.53352691396202E-08"
        iyy="0.00167924016665455"
        iyz="3.96441663275016E-07"
        izz="0.0028869008381509" />
    </inertial>
    <visual>
      <!-- <origin
        xyz="0 0 0"
        rpy="0 0 0" />
      <geometry>
        <mesh
          filename="package://smrr_description/meshes/left_wheel.STL" />
      </geometry> -->
      <origin
        xyz="0 0 0.025"
        rpy="0 0 0" />
       <geometry>
        <cylinder radius="0.081" length="0.05"/>
      </geometry>
      <material
        name="">
        <color
          rgba="0.2 0.2 0.2 1" />
      </material>
    </visual>
    <collision>
      <origin
        xyz="0 0 0.025"
        rpy="0 0 0" />
       <geometry>
        <cylinder radius="0.081" length="0.05"/>
      </geometry>
      <!-- <geometry>
        <cylinder radius="0.05" length="0.03"/>
      </geometry> -->
    </collision>
  </link>
  <!-- <joint
    name="left_wheel_joint"
    type="continuous">
    <origin
      xyz="0 0.201 0.0183999999999997"
      rpy="-1.5707963267949 0 0" />
    <parent
      link="base_link" />
    <child
      link="left_wheel" />
    <axis
      xyz="0 0 1" />
  </joint> -->
      <joint
      name="left_wheel_joint"
      type="continuous">
      <origin
        xyz="0 0.201 0.0183999999999997"
        rpy="-1.5707963267949 0 0" />
      <parent
        link="base_link" />
      <child
        link="left_wheel" />
      <axis
        xyz="0 0 1" />
      <dynamics damping="0.3" friction="0.5"/>
  </joint>

  <link
    name="front_caster">
    <inertial>
      <origin
        xyz="0 0 -0.0025"
        rpy="0 0 0" />
      <mass
        value="0.0335103216382911" />
      <inertia
        ixx="5.36165146212658E-06"
        ixy="0"
        ixz="-9.4039548065783E-38"
        iyy="5.36165146212658E-06"
        iyz="0"
        izz="5.36165146212658E-06" />
    </inertial>
    <visual>
      <origin
        xyz="0 0 0.03"
        rpy="0 0 0" />
      <!-- <geometry>
        <mesh
          filename="package://smrr_description/meshes/front_caster.STL" />
      </geometry> -->
      <geometry>
          <sphere radius="0.05"/>
        </geometry>
      <material
        name="">
        <color
          rgba="0.537254901960784 0.349019607843137 0.337254901960784 1" />
      </material>
    </visual>
    <collision>
      <origin
        xyz="0 0 0.03"
        rpy="0 0 0" />
      <!-- <geometry>
        <mesh
          filename="package://smrr_description/meshes/front_caster.STL" />
      </geometry> -->
      <geometry>
          <sphere radius="0.05"/>
        </geometry>
    </collision>
  </link>
  <!-- <joint
    name="front_caster_joint"
    type="continuous">
    <origin
      xyz="0.245 0 -0.04"
      rpy="0 0 0" />
    <parent
      link="base_link" />
    <child
      link="front_caster" />
    <axis
      xyz="1 0 0" />
  </joint> -->
  <joint
    name="front_caster_joint"
    type="fixed">
    <origin
      xyz="0.245 0 -0.04"
      rpy="0 0 0" />
    <parent
      link="base_link" />
    <child
      link="front_caster" />
    <axis
      xyz="1 0 0" />
  </joint>
  <link
    name="back_caster">
    <inertial>
      <origin
        xyz="0 0 -0.0025"
        rpy="0 0 0" />
      <mass
        value="0.0335103216382911" />
      <inertia
        ixx="5.36165146212658E-06"
        ixy="0"
        ixz="-9.4039548065783E-38"
        iyy="5.36165146212658E-06"
        iyz="0"
        izz="5.36165146212658E-06" />
    </inertial>
    <visual>
      <origin
        xyz="0 0 0.03"     
        rpy="0 0 0" /> <!-- -0.0025 -->
      <!-- <geometry>
        <mesh
          filename="package://smrr_description/meshes/back_caster.STL" />
      </geometry> -->
       <geometry>
          <sphere radius="0.05"/>
        </geometry>
      <material
        name="">
        <color
          rgba="0.537254901960784 0.349019607843137 0.337254901960784 1" />
      </material>
    </visual>
    <collision>
      <origin
        xyz="0 0 0.03"
        rpy="0 0 0" />
        <geometry>
          <sphere radius="0.05"/>
        </geometry>
      <!-- <geometry>
        <mesh
          filename="package://smrr_description/meshes/back_caster.STL" />
      </geometry> -->
    </collision>
  </link>
  <!-- <joint
    name="back_caster_joint"
    type="continuous">
    <origin
      xyz="-0.245 0 -0.04"
      rpy="0 0 0" />
    <parent
      link="base_link" />
    <child
      link="back_caster" />
    <axis
      xyz="1 0 0" />
  </joint> -->
  <joint
    name="back_caster_joint"
    type="fixed">
    <origin
      xyz="-0.245 0 -0.04"
      rpy="0 0 0" />
    <parent
      link="base_link" />
    <child
      link="back_caster" />
    <axis
      xyz="1 0 0" />
  </joint>
  <link
    name="shoulder_r_link">
    <inertial>
      <origin
        xyz="-0.00092585 -0.073571 -0.0014299"
        rpy="0 0 0" />
      <!-- <mass
        value="0.48651" /> -->
      <mass
        value="0.048651" />
      <inertia
        ixx="0.00069334"
        ixy="-1.5427E-05"
        ixz="-1.4012E-05"
        iyy="0.00048243"
        iyz="-1.2029E-05"
        izz="0.00087094" />
    </inertial>
    <visual>
      <origin
        xyz="0 0 0"
        rpy="0 0 0" />
      <geometry>
        <mesh
          filename="package://smrr_description/meshes/shoulder_r_link.STL" />
      </geometry>
      <material
        name="">
        <color
          rgba="0.79216 0.81961 0.93333 1" />
      </material>
    </visual>
    <collision>
      <origin
        xyz="0 0 0"
        rpy="0 0 0" />
      <geometry>
        <mesh
          filename="package://smrr_description/meshes/shoulder_r_link.STL" />
      </geometry>
    </collision>
  </link>
  <joint
    name="shoulder_r_joint"
    type="revolute">
    <origin
      xyz="0.0025 -0.17549 1.13"
      rpy="1.5708 0 0" />
    <parent
      link="base_link" />
    <child
      link="shoulder_r_link" />
    <axis
      xyz="0 0 1" />
    <limit
      lower="0"
      upper="${0.5*PI}"
      effort="0"
      velocity="0" />
  </joint>
  <link
    name="bicep_r_link">
    <inertial>
      <origin
        xyz="0.00456419739967517 0.00249181873032056 0.0620811730205644"
        rpy="0 0 0" />
      <!-- <mass
        value="0.538762310699068" /> -->
        <mass
        value="0.0538762310699068" />
      <inertia
        ixx="0.00110007999534321"
        ixy="6.64756733254256E-06"
        ixz="-6.42278471778445E-05"
        iyy="0.00100542318480344"
        iyz="-2.88448489732389E-05"
        izz="0.000397423248392103" />
    </inertial>
    <visual>
      <origin
        xyz="0 0 0"
        rpy="0 0 0" />
      <geometry>
        <mesh
          filename="package://smrr_description/meshes/bicep_r_link.STL" />
      </geometry>
      <material
        name="">
        <color
          rgba="0.792156862745098 0.819607843137255 0.933333333333333 1" />
      </material>
    </visual>
    <collision>
      <origin
        xyz="0 0 0"
        rpy="0 0 0" />
      <geometry>
        <mesh
          filename="package://smrr_description/meshes/bicep_r_link.STL" />
      </geometry>
    </collision>
  </link>
  <joint
    name="bicep_r_joint"
    type="revolute">
    <origin
      xyz="-0.00044422 -0.12491 -0.0013064"
      rpy="3.1416 -1.5388 -1.4874" />
    <parent
      link="shoulder_r_link" />
    <child
      link="bicep_r_link" />
    <axis
      xyz="0 0 1" />
    <limit
      lower="${-0.25*PI}"
      upper="${0.25*PI}"
      effort="0"
      velocity="0" />
  </joint>
  <link
    name="elbow_r_link">
    <inertial>
      <origin
        xyz="0.0189012713612922 -0.104494121653016 0.0037361706207345"
        rpy="0 0 0" />
      <!-- <mass
        value="0.707311793414628" /> -->
        <mass
        value="0.0707311793414628" />
      <inertia
        ixx="0.00317831610049729"
        ixy="0.000730842285215937"
        ixz="-3.92196962836598E-05"
        iyy="0.00056476639828066"
        iyz="9.72253921244881E-05"
        izz="0.00345384756415845" />
    </inertial>
    <visual>
      <origin
        xyz="0 0 0"
        rpy="0 0 0" />
      <geometry>
        <mesh
          filename="package://smrr_description/meshes/elbow_r_link.STL" />
      </geometry>
      <material
        name="">
        <color
          rgba="1 1 1 1" />
      </material>
    </visual>
    <collision>
      <origin
        xyz="0 0 0"
        rpy="0 0 0" />
      <geometry>
        <mesh
          filename="package://smrr_description/meshes/elbow_r_link.STL" />
      </geometry>
    </collision>
  </link>
  <joint
    name="elbow_r_joint"
    type="revolute">
    <origin
      xyz="0.010186 -0.0047446 0.14136"
      rpy="-1.6029 -0.083354 -1.5681" />
    <parent
      link="bicep_r_link" />
    <child
      link="elbow_r_link" />
    <axis
      xyz="-0.06561 0.035186 0.99722" />
    <limit
      lower="0"
      upper="${0.5*PI}"
      effort="0"
      velocity="0" />
  </joint>
  <link
    name="wrist_r_link">
    <inertial>
      <origin
        xyz="0.00536422325041863 -0.00389024639618119 0.0585391850650762"
        rpy="0 0 0" />
      <!-- <mass
        value="0.251020752919746" /> -->
        <mass
        value="0.0251020752919746" />
      <inertia
        ixx="0.000465383132851358"
        ixy="2.98567445220425E-05"
        ixz="-1.25755488169422E-05"
        iyy="0.00049573093541797"
        iyz="4.38216902241107E-05"
        izz="0.000150215820080147" />
    </inertial>
    <visual>
      <origin
        xyz="0 0 0"
        rpy="0 0 0" />
      <geometry>
        <mesh
          filename="package://smrr_description/meshes/wrist_r_link.STL" />
      </geometry>
      <material
        name="">
        <color
          rgba="1 1 1 1" />
      </material>
    </visual>
    <collision>
      <origin
        xyz="0 0 0"
        rpy="0 0 0" />
      <geometry>
        <mesh
          filename="package://smrr_description/meshes/wrist_r_link.STL" />
      </geometry>
    </collision>
  </link>
  <joint
    name="wrist_r_joint"
    type="revolute">
    <origin
      xyz="0.057171 -0.23705 0.0080661"
      rpy="1.6119 -0.056547 0.21793" />
    <parent
      link="elbow_r_link" />
    <child
      link="wrist_r_link" />
    <axis
      xyz="0 0 1" />
    <limit
      lower="${-0.25*PI}"
      upper="${0.25*PI}"
      effort="0"
      velocity="0" />
  </joint>

  <link name="eef_r_link" />
  <joint name="eef_r_joint" type="fixed">
    <origin xyz="0.04 0.0 0.13" rpy="0 0 0" />
    <parent link="wrist_r_link" />
    <child link="eef_r_link" />
  </joint>

  <link
    name="shoulder_l_link">
    <inertial>
      <origin
        xyz="-0.00223171459040639 0.0735077610887185 -0.00727072527860662"
        rpy="0 0 0" />
      <!-- <mass
        value="0.486619623596047" /> -->
        <mass
        value="0.0486619623596047" />
      <inertia
        ixx="0.000691148104143343"
        ixy="2.23070508431298E-05"
        ixz="-1.44584722184453E-06"
        iyy="0.000483395276258092"
        iyz="8.83940633277041E-06"
        izz="0.0008722354231839" />
    </inertial>
    <visual>
      <origin
        xyz="0 0 0"
        rpy="0 0 0" />
      <geometry>
        <mesh
          filename="package://smrr_description/meshes/shoulder_l_link.STL" />
      </geometry>
      <material
        name="">
        <color
          rgba="0.792156862745098 0.819607843137255 0.933333333333333 1" />
      </material>
    </visual>
    <collision>
      <origin
        xyz="0 0 0"
        rpy="0 0 0" />
      <geometry>
        <mesh
          filename="package://smrr_description/meshes/shoulder_l_link.STL" />
      </geometry>
    </collision>
  </link>
  <joint
    name="shoulder_l_joint"
    type="fixed">
    <origin
      xyz="0.0025 0.17451 1.13"
      rpy="-1.5708 0 0" />
    <parent
      link="base_link" />
    <child
      link="shoulder_l_link" />
    <axis
      xyz="0 0 0" />
  </joint>
  <link
    name="bicep_l_link">
    <inertial>
      <origin
        xyz="0.000454794202440767 -0.00611220620485536 0.0539125460090588"
        rpy="0 0 0" />
      <!-- <mass
        value="0.538778957177395" /> -->
        <mass
        value="0.0538778957177395" />
      <inertia
        ixx="0.00107418581685125"
        ixy="-4.27051446432224E-05"
        ixz="-4.34568581105098E-05"
        iyy="0.00103125455171258"
        iyz="5.54075320065143E-05"
        izz="0.000397405933232645" />
    </inertial>
    <visual>
      <origin
        xyz="0 0 0"
        rpy="0 0 0" />
      <geometry>
        <mesh
          filename="package://smrr_description/meshes/bicep_l_link.STL" />
      </geometry>
      <material
        name="">
        <color
          rgba="1 1 1 1" />
      </material>
    </visual>
    <collision>
      <origin
        xyz="0 0 0"
        rpy="0 0 0" />
      <geometry>
        <mesh
          filename="package://smrr_description/meshes/bicep_l_link.STL" />
      </geometry>
    </collision>
  </link>
  <joint
    name="bicep_l_joint"
    type="fixed">
    <origin
      xyz="0 0.132886516674827 -0.0060335882458285"
      rpy="-1.63198776689551 -1.01581788387206 0" />
    <parent
      link="shoulder_l_link" />
    <child
      link="bicep_l_link" />
    <axis
      xyz="0 0 0" />
  </joint>
  <link
    name="elbow_l_link">
    <inertial>
      <origin
        xyz="-0.0173747200487513 -0.104785947380545 -0.0011292843884021"
        rpy="0 0 0" />
      <!-- <mass
        value="0.707425243711934" /> -->
        <mass
        value="0.0707425243711934" />
      <inertia
        ixx="0.00319627340039183"
        ixy="-0.000696565704702898"
        ixz="1.06171600234816E-05"
        iyy="0.000542584103977577"
        iyz="1.31729445005138E-06"
        izz="0.0034583302113884" />
    </inertial>
    <visual>
      <origin
        xyz="0 0 0"
        rpy="0 0 0" />
      <geometry>
        <mesh
          filename="package://smrr_description/meshes/elbow_l_link.STL" />
      </geometry>
      <material
        name="">
        <color
          rgba="1 1 1 1" />
      </material>
    </visual>
    <collision>
      <origin
        xyz="0 0 0"
        rpy="0 0 0" />
      <geometry>
        <mesh
          filename="package://smrr_description/meshes/elbow_l_link.STL" />
      </geometry>
    </collision>
  </link>
  <joint
    name="elbow_l_joint"
    type="fixed">
    <origin
      xyz="0.0105772159798597 -0.0030571404655029 0.13340214960524"
      rpy="-1.64338471983846 0.0522094259130711 -2.1200306963474" />
    <parent
      link="bicep_l_link" />
    <child
      link="elbow_l_link" />
    <axis
      xyz="0 0 0" />
  </joint>
  <link
    name="wrist_l_link">
    <inertial>
      <origin
        xyz="0.0209300830878604 0.00271510348029902 0.0642203252538052"
        rpy="0 0 0" />
      <!-- <mass
        value="0.251035354848779" /> -->
        <mass
        value="0.0251035354848779" />
      <inertia
        ixx="0.000431886118305991"
        ixy="-2.67253404726276E-05"
        ixz="-8.06480905192447E-05"
        iyy="0.00050803498415842"
        iyz="-3.47935493314316E-05"
        izz="0.000171458123713197" />
    </inertial>
    <visual>
      <origin
        xyz="0 0 0"
        rpy="0 0 0" />
      <geometry>
        <mesh
          filename="package://smrr_description/meshes/wrist_l_link.STL" />
      </geometry>
      <material
        name="">
        <color
          rgba="1 1 1 1" />
      </material>
    </visual>
    <collision>
      <origin
        xyz="0 0 0"
        rpy="0 0 0" />
      <geometry>
        <mesh
          filename="package://smrr_description/meshes/wrist_l_link.STL" />
      </geometry>
    </collision>
  </link>
  <joint
    name="wrist_l_joint"
    type="fixed">
    <origin
      xyz="-0.0475575242502448 -0.230767174560738 0.00284774101317437"
      rpy="-1.64563125617647 -0.00657240831041781 -3.14132527572016" />
    <parent
      link="elbow_l_link" />
    <child
      link="wrist_l_link" />
    <axis
      xyz="0 0 0" />
  </joint>
</robot>